<mujoco model="xarm6">
  <compiler angle="radian" autolimits="true" meshdir="meshes"/>

  <option integrator="implicitfast"/>

  <asset>
    <material name="white" rgba="1 1 1 1"/>
    <material name="gray" rgba="0.753 0.753 0.753 1"/>
    <material name="black" rgba="0.149 0.149 0.149 1"/>

    <mesh file="link_base.stl"/>
    <mesh file="link1.stl"/>
    <mesh file="link2.stl"/>
    <mesh file="link3.stl"/>
    <mesh file="link4.stl"/>
    <mesh file="link5.stl"/>
    <mesh file="end_tool.stl"/>
    <mesh file="base_link.stl"/>
    <mesh file="left_outer_knuckle.stl"/>
    <mesh file="left_finger.stl"/>
    <mesh file="left_inner_knuckle.stl"/>
    <mesh file="right_outer_knuckle.stl"/>
    <mesh file="right_finger.stl"/>
    <mesh file="right_inner_knuckle.stl"/>
  </asset>

  <default>
    <default class="xarm6">
      <geom type="mesh" material="white"/>
      <joint axis="0 0 1" range="-6.28319 6.28319" frictionloss="1"/>
      <general biastype="affine" ctrlrange="-6.28319 6.28319"/>
      <default class="size1">
        <joint damping="10"/>
        <general gainprm="1500" biasprm="0 -1500 -150" forcerange="-50 50"/>
      </default>
      <default class="size2">
        <joint damping="5"/>
        <general gainprm="1000" biasprm="0 -1000 -100" forcerange="-30 30"/>
      </default>
      <default class="size3">
        <joint damping="2"/>
        <general gainprm="800" biasprm="0 -800 -80" forcerange="-20 20"/>
      </default>
       <default class="spring_link">
        <joint range="0 0.85" stiffness="0.05" springref="2.62" damping="0.00125"/>
      </default>
      <default class="driver">
        <joint range="0 0.85" armature="0.005" damping="0.1" solreflimit="0.005 1"/>
      </default>
      <default class="follower">
        <joint range="0 0.85" solreflimit="0.005 1"/>
      </default>
      <site size="0.001" rgba="1 0 0 1" group="4"/>
    </default>
      <default class="collision">
      <geom group="0" condim="3"/>
    </default>
  </default>
  
  <worldbody>
    <body name="link_base" pos="0 0 0.061" childclass="xarm6">
      <geom mesh="link_base"/>
      <body name="link1" pos="0 0 0.0915">
        <joint name="joint1" class="size1"/>
        <geom mesh="link1"/>
        <body name="link2" pos="0 0.0775 0.115" quat="1 -1 0 0">
          <joint name="joint2" range="-2.059 2.0944" class="size1"/>
          <geom mesh="link2"/>
          <body name="link3" pos="0.053 -0.28478 -0.00817" quat="0 0 0 1">
            <joint name="joint3" class="size2"/>
            <geom mesh="link3"/>
            <body name="link4" pos="-0.08578 -0.16933 -0.06658" quat="0.5 0.5 -0.5 0.5">
              <joint name="joint4" class="size2"/>
              <geom mesh="link4"/>
              <body name="link5" pos="0 0 0.13555" quat="0.5 -0.5 0.5 -0.5 ">
                <joint name="joint5" class="size2"/>
                <geom mesh="link5"/>
                <body name="link6" pos="-0.077 -0.071 0" quat="0.5 0.5 -0.5 0.5">
                  <joint name="joint6" class="size3"/>
                  <geom material="gray" mesh="end_tool"/>
                  <body name="xarm_gripper_base_link" pos="0 0 0.028" quat="0.707 0 0 -0.707">
                    <geom mesh="base_link"/>
                    
                    <body name="ee_center_body" pos="0 0 0.18">
                      <site name="ee_center_site" size="0.01" group="3"/>
                      <!-- Adjusting position and size for better visibility -->
                      <geom name="end_effector" class = "collision" type="box" size="0.005 0.005 0.005" rgba="1 0 0 1"/>
                    </body>

                    <body name="left_outer_knuckle" pos="0 0.035 0.059098">
                      <joint name="left_driver_joint" axis="1 0 0" class="driver"/>
                      <geom material="black" mesh="left_outer_knuckle"/>
                      <body name="left_finger" pos="0 0.035465 0.042039">
                        <joint name="left_finger_joint" axis="-1 0 0" class="follower"/>
                        <geom material="black" mesh="left_finger"/>
                      </body>
                    </body>
                    <body name="left_inner_knuckle" pos="0 0.02 0.074098">
                      <joint name="left_inner_knuckle_joint" axis="1 0 0" class="spring_link"/>
                      <geom material="black" mesh="left_inner_knuckle"/>
                    </body>
                    <body name="right_outer_knuckle" pos="0 -0.035 0.059098">
                      <joint name="right_driver_joint" axis="-1 0 0" class="driver"/>
                      <geom material="black" mesh="right_outer_knuckle"/>
                      <body name="right_finger" pos="0 -0.035465 0.042039"> 
                        <joint name="right_finger_joint" axis="1 0 0" class="follower"/>
                        <geom material="black" mesh="right_finger"/>
                      </body>
                    </body>
                    <body name="right_inner_knuckle" pos="0 -0.02 0.074098">
                      <joint name="right_inner_knuckle_joint" axis="-1 0 0" class="spring_link"/>
                      <geom material="black" mesh="right_inner_knuckle"/>
                    </body>
                  </body>
                </body>
              </body>
            </body>
          </body>
       </body>
      </body>
    </body>
  </worldbody>

  <contact>
    <exclude body1="right_inner_knuckle" body2="right_outer_knuckle"/>
    <exclude body1="right_inner_knuckle" body2="right_finger"/>
    <exclude body1="left_inner_knuckle" body2="left_outer_knuckle"/>
    <exclude body1="left_inner_knuckle" body2="left_finger"/>
  </contact>

  <tendon>
    <fixed name="split">
      <joint joint="right_driver_joint" coef="0.5"/>
      <joint joint="left_driver_joint" coef="0.5"/>
    </fixed>
  </tendon>

  <equality>
    <connect anchor="0 0.015 0.015" body1="right_finger" body2="right_inner_knuckle" solref="0.005 1"/>
    <connect anchor="0 -0.015 0.015" body1="left_finger" body2="left_inner_knuckle" solref="0.005 1"/>
    <joint joint1="left_driver_joint" joint2="right_driver_joint" polycoef="0 1 0 0 0" solref="0.005 1"/>
  </equality>

  <actuator>
    <general name="act1" joint="joint1" class="size1"/>
    <general name="act2" joint="joint2" class="size1" ctrlrange="-2.05 2.05"/>
    <general name="act3" joint="joint3" class="size2" ctrlrange="0 3.9"/>
    <general name="act4" joint="joint4" class="size2"/>
    <general name="act5" joint="joint5" class="size3" ctrlrange="-1.67 3.12"/>
    <general name="act6" joint="joint6" class="size3"/>
    <general name="gripper" tendon="split" forcerange="-50 50" ctrlrange="0 255" biastype="affine" gainprm="0.333" biasprm="0 -100 -10"/>
  </actuator>

</mujoco>